Workbook

Sheet Criteria
A1: ID | B1: Criterion | C1: Target | D1: Measured | E1: Out of / threshold | F1: Status
A2: C1 | B2: Functional correctness | C2: 14 of 14 | D2: =COUNTIF(Exp1!$D$2:$D$15,"PASS") | E2: 14 | F2: =IF(D2=E2,"met","not met")
A3: C2 | B3: Detection rate | C3: 100% | D3: =COUNTIF(Exp3!$I$2:$I$501,">=1") | E3: =COUNTA(Exp3!$A$2:$A$501) | F3: =IF(D3=E3,"met","not met")
A4: C3 | B4: False positives | C4: 0 | D4: =Exp1!G6 | E4: 0 | F4: =IF(D4=E4,"met","not met")
A5: C4 | B5: Cipher list accuracy | C5: 100% | D5: =COUNTIF(Exp3!$V$2:$V$501,TRUE) | E5: =COUNTIF(Exp3!$N$2:$N$501,TRUE) | F5: =IF(D5=E5,"met","not met")
A6: C5 | B6: Version accuracy | C6: 100% | D6: =COUNTIF(Exp3!$W$2:$W$501,TRUE) | E6: =COUNTIF(Exp3!$O$2:$O$501,TRUE) | F6: =IF(D6=E6,"met","not met")
A7: C6 | B7: False certainty | C7: 0 | D7: =COUNTIF(Exp3!$V$2:$V$501,FALSE)+COUNTIF(Exp3!$W$2:$W$501,FALSE)+COUNTIF(Exp3!$T$2:$T$501,FALSE)+COUNTIF(Exp3!$U$2:$U$501,FALSE) | E7: 0 | F7: =IF(D7=E7,"met","not met")
A8: C7 | B8: Container attribution | C8: 100% | D8: =COUNTIF(Exp3!$X$2:$X$501,TRUE) | E8: =COUNTA(Exp3!$A$2:$A$501) | F8: =IF(D8=E8,"met","not met")
A9: C8 | B9: Truncation reporting (split flagged) | C9: 100% | D9: =COUNTIFS(Exp4!$K$2:$K$1441,TRUE,Exp4!$L$2:$L$1441,TRUE) | E9: =COUNTIF(Exp4!$K$2:$K$1441,TRUE) | F9: =IF(D9=E9,"met","not met")
A10: C8 | B10: Truncation reporting (fits but flagged) | C10: 0 | D10: =COUNTIFS(Exp4!$K$2:$K$1441,FALSE,Exp4!$L$2:$L$1441,TRUE) | E10: 0 | F10: =IF(D10=E10,"met","not met")
A11: C9 | B11: Fragmentation coverage | C11: tested against H1 to H3 | D11: H1 holds except openssl MLKEM768 (pure PQ) at 1500-off: fits | E11: see Exp4_coverage | F11: reported
A12: C10 | B12: Verdict agreement | C12: 100% | D12: =COUNTIF(Exp3!$Y$2:$Y$501,TRUE) | E12: =COUNTIF(Exp3!$R$2:$R$501,"<>unknown") | F12: =IF(D12=E12,"met","not met")
A13: C11 | B13: Enforcement accuracy (rows 8 to 10) | C13: all pass | D13: =COUNTIF(Exp1!$D$9:$D$11,"PASS") | E13: 3 | F13: =IF(D13=E13,"met","not met")
A14: C12 | B14: Safe failure (rows 9, 11 to 13) | C14: all hold | D14: =COUNTIF(Exp1!$D$10,"PASS")+COUNTIF(Exp1!$D$12:$D$14,"PASS") | E14: 4 | F14: =IF(D14=E14,"met","not met")
A15: C13 | B15: Handshake overhead, worst change | C15: under 5% | D15: =MAX(ABS(MEDIAN(Exp5_cost!$E$12:$E$21)/MEDIAN(Exp5_cost!$E$2:$E$11)-1),ABS(MEDIAN(Exp5_cost!$E$22:$E$31)/MEDIAN(Exp5_cost!$E$2:$E$11)-1)) | E15: 0.05 | F15: =IF(D15<E15,"met","not met")
A16: C14 | B16: Kernel cost per call, enforce (ns) | C16: reported | D16: =AVERAGEIFS(Exp5_stats!$F$2:$F$7,Exp5_stats!$A$2:$A$7,"enforce") | F16: reported
A17: C15 | B17: Event loss in experiment 5 | C17: 0 | D17: =SUM(Exp5_cost!$H$2:$H$31)+SUM(Exp5_stats!$G$2:$G$7)+SUM(Exp5_tput!$F$2:$F$16)+Exp5_latency!F4+SUM(Exp5_policy!$H$2:$H$21) | E17: 0 | F17: =IF(D17=E17,"met","not met")
A18: C16 | B18: Robustness: false complete fields | C18: 0 | D18: =SUM(Exp3_fuzz!$I$2:$I$5006) | E18: 0 | F18: =IF(D18=E18,"met","not met")
A19: C17 | B19: Data-path overhead, worst change | C19: under 5% | D19: =MAX(ABS(MEDIAN(Exp5_tput!$E$7:$E$11)/MEDIAN(Exp5_tput!$E$2:$E$6)-1),ABS(MEDIAN(Exp5_tput!$E$12:$E$16)/MEDIAN(Exp5_tput!$E$2:$E$6)-1)) | E19: 0.05 | F19: =IF(D19<E19,"met","not met")
A20: C18 | B20: Tail latency p99, worst change | C20: under 10% | D20: =MAX(Exp5_latency!G3/Exp5_latency!F3-1,Exp5_latency!H3/Exp5_latency!F3-1) | E20: 0.1 | F20: =IF(D20<E20,"met","not met")
A21: C19 | B21: Policy scalability, 1 to 64 rules | C21: under 5% | D21: =MAX(ABS(MEDIAN(Exp5_policy!$F$12:$F$16)/MEDIAN(Exp5_policy!$F$2:$F$6)-1),ABS(MEDIAN(Exp5_policy!$F$17:$F$21)/MEDIAN(Exp5_policy!$F$2:$F$6)-1)) | E21: 0.05 | F21: =IF(D21<E21,"met","not met")
A22: C19 | B22: Policy scalability, 1 against 30 ciphers | C22: under 5% | D22: =ABS(MEDIAN(Exp5_policy!$F$7:$F$11)/MEDIAN(Exp5_policy!$F$2:$F$6)-1) | E22: 0.05 | F22: =IF(D22<E22,"met","not met")
A23: C20 | B23: Saturation: highest rate with no drop (per s) | C23: reported | D23: =_xlfn.MAXIFS(Exp5_sat!$D$2:$D$5,Exp5_sat!$F$2:$F$5,0) | F23: reported
A24: C21 | B24: Footprint: JIT bytes | C24: reported | D24: =Exp5_footprint!B3 | F24: reported
A25: C22 | B25: Enforcement at scale | C25: 100% | D25: =COUNTIF(Exp6_matrix!$I$2:$I$73,TRUE) | E25: =COUNTA(Exp6_matrix!$A$2:$A$73) | F25: =IF(D25=E25,"met","not met")
A26: C23 | B26: Scenario validation | C26: all | D26: =COUNTIFS(Exp6_scenarios!$B$2:$B$4,"<>allow",Exp6_scenarios!$D$2:$D$4,TRUE) | E26: =COUNTA(Exp6_scenarios!$A$2:$A$4) | F26: =IF(D26=E26,"met","not met")
A27: C24 | B27: Attribution under concurrency | C27: 100%, none unnamed | D27: =SUM(Exp7!$I$2:$I$61) | E27: =SUM(Exp7!$H$2:$H$61) | F27: =IF(D27=E27,"met","not met")
A28: C25 | B28: Grade agreement | C28: 100% | D28: =COUNTIF(Exp3!$AC$2:$AC$501,TRUE) | E28: =COUNTIF(Exp3!$AB$2:$AB$501,TRUE) | F28: =IF(D28=E28,"met","not met")

Sheet Exp1
A1: No | B1: Function | C1: Evidence | D1: Result | F1: C3 traffic | G1: Value
A2: 1 | B2: Detect a ClientHello | C2: verify-M3: one event per TLS case | D2: PASS | F2: SSH connections | G2: 1
A3: 2 | B3: Ignore other traffic | C3: verify-M3 plaintext (HTTP), verify-M6.6 junk; here: 1 SSH and 100 random-byte connections, 101 received with 409621 bytes, 0 events | D3: PASS | F3: Random-byte connections | G3: 100
A4: 3 | B4: Read the cipher suites | C4: verify-M3 tls12_two, tls13_one, cipher_cap | D4: PASS | F4: Connections received | G4: 101
A5: 4 | B5: Read the versions | C5: verify-M3 tls12_two, tls13_one, default_small | D5: PASS | F5: Bytes received | G5: 409621
A6: 5 | B6: Flag a split ClientHello | C6: verify-M3 default_pqc, versions_cut | D6: PASS | F6: skbouncer events | G6: 0
A7: 6 | B7: Name the container | C7: verify-M4 shared network namespace; verify-M5 five containers, one veth | D7: PASS
A8: 7 | B8: Audit a violation | C8: verify-M5 | D8: PASS
A9: 8 | B9: Enforce a violation | C9: verify-M6 ports 4472, 4473 | D9: PASS
A10: 9 | B10: Fail open | C10: verify-M6 port 4475 | D10: PASS
A11: 10 | B11: Block unknown on request | C11: verify-M6 port 4478 | D11: PASS
A12: 11 | B12: Refuse the root cgroup | C12: verify-M6 refusal root_cgroup | D12: PASS
A13: 12 | B13: Refuse a non-veth in enforce mode | C13: verify-M6 refusal not_a_veth (lo) | D13: PASS
A14: 13 | B14: Detach on exit | C14: verify-M6.6 deaths (SIGPIPE, SIGHUP, SIGUSR2), coexist (SIGINT) | D14: PASS
A15: 14 | B15: Control | C15: here: row 8's client, skbouncer stopped: attached 0, established True, server got the ClientHello True | D15: PASS

Sheet Exp3
A1: Run | B1: Client | C1: Container | D1: Port | E1: Server record_len | F1: Server legacy_version | G1: Server ciphers | H1: Server versions | I1: Events | J1: Event container | K1: Event record_len | L1: Event legacy_version | M1: captured_len | N1: ciphers_seen | O1: versions_seen | P1: Event ciphers | Q1: Event versions | R1: Verdict | S1: Reference verdict | T1: record_len match | U1: legacy match | V1: Cipher match | W1: Version match | X1: Named correctly | Y1: Verdict agrees | Z1: Grade (skbouncer) | AA1: Grade (server) | AB1: Read in full | AC1: Grade agrees
A2: census | B2: openssl 3.5.8 default | C2: skb-eval-8352-c5001 | D2: 5001 | E2: 1543 | F2: 771 | G2: 1302 1303 1301 c02c c030 009f cca9 cca8 ccaa c02b c02f 009e c024 c028 006b c023 c027 0067 c00a c014 0039 c009 c013 0033 009d 009c 003d 003c 0035 002f | H2: 0304 0303 | I2: 1 | J2: skb-eval-8352-c5001 | K2: 1543 | L2: 771 | M2: 1443 | N2: TRUE | O2: TRUE | P2: 1302 1303 1301 c02c c030 009f cca9 cca8 ccaa c02b c02f 009e c024 c028 006b c023 c027 0067 c00a c014 0039 c009 c013 0033 009d 009c 003d 003c 0035 002f | Q2: 0304 0303 | R2: violation | S2: violation | T2: =K2=E2 | U2: =L2=F2 | V2: =IF(N2,EXACT(P2,G2),"") | W2: =IF(O2,EXACT(Q2,H2),"") | X2: =J2=C2 | Y2: =IF(R2="unknown","",R2=S2) | Z2: A | AA2: A | AB2: =AND(N2,O2,A2<>"census-mixed") | AC2: =IF(AB2,Z2=AA2,"")
A3: census | B3: openssl 3.5.8 default | C3: skb-eval-8352-c5002 | D3: 5002 | E3: 1543 | F3: 771 | G3: 1302 1303 1301 c02c c030 009f cca9 cca8 ccaa c02b c02f 009e c024 c028 006b c023 c027 0067 c00a c014 0039 c009 c013 0033 009d 009c 003d 003c 0035 002f | H3: 0304 0303 | I3: 1 | J3: skb-eval-8352-c5002 | K3: 1543 | L3: 771 | M3: 1443 | N3: TRUE | O3: TRUE | P3: 1302 1303 1301 c02c c030 009f cca9 cca8 ccaa c02b c02f 009e c024 c028 006b c023 c027 0067 c00a c014 0039 c009 c013 0033 009d 009c 003d 003c 0035 002f | Q3: 0304 0303 | R3: violation | S3: violation | T3: =K3=E3 | U3: =L3=F3 | V3: =IF(N3,EXACT(P3,G3),"") | W3: =IF(O3,EXACT(Q3,H3),"") | X3: =J3=C3 | Y3: =IF(R3="unknown","",R3=S3) | Z3: A | AA3: A | AB3: =AND(N3,O3,A3<>"census-mixed") | AC3: =IF(AB3,Z3=AA3,"")
A4: census | B4: openssl 3.5.8 default | C4: skb-eval-8352-c5003 | D4: 5003 | E4: 1543 | F4: 771 | G4: 1302 1303 1301 c02c c030 009f cca9 cca8 ccaa c02b c02f 009e c024 c028 006b c023 c027 0067 c00a c014 0039 c009 c013 0033 009d 009c 003d 003c 0035 002f | H4: 0304 0303 | I4: 1 | J4: skb-eval-8352-c5003 | K4: 1543 | L4: 771 | M4: 1443 | N4: TRUE | O4: TRUE | P4: 1302 1303 1301 c02c c030 009f cca9 cca8 ccaa c02b c02f 009e c024 c028 006b c023 c027 0067 c00a c014 0039 c009 c013 0033 009d 009c 003d 003c 0035 002f | Q4: 0304 0303 | R4: violation | S4: violation | T4: =K4=E4 | U4: =L4=F4 | V4: =IF(N4,EXACT(P4,G4),"") | W4: =IF(O4,EXACT(Q4,H4),"") | X4: =J4=C4 | Y4: =IF(R4="unknown","",R4=S4) | Z4: A | AA4: A | AB4: =AND(N4,O4,A4<>"census-mixed") | AC4: =IF(AB4,Z4=AA4,"")
A5: census | B5: openssl 3.5.8 default | C5: skb-eval-8352-c5004 | D5: 5004 | E5: 1543 | F5: 771 | G5: 1302 1303 1301 c02c c030 009f cca9 cca8 ccaa c02b c02f 009e c024 c028 006b c023 c027 0067 c00a c014 0039 c009 c013 0033 009d 009c 003d 003c 0035 002f | H5: 0304 0303 | I5: 1 | J5: skb-eval-8352-c5004 | K5: 1543 | L5: 771 | M5: 1443 | N5: TRUE | O5: TRUE | P5: 1302 1303 1301 c02c c030 009f cca9 cca8 ccaa c02b c02f 009e c024 c028 006b c023 c027 0067 c00a c014 0039 c009 c013 0033 009d 009c 003d 003c 0035 002f | Q5: 0304 0303 | R5: violation | S5: violation | T5: =K5=E5 | U5: =L5=F5 | V5: =IF(N5,EXACT(P5,G5),"") | W5: =IF(O5,EXACT(Q5,H5),"") | X5: =J5=C5 | Y5: =IF(R5="unknown","",R5=S5) | Z5: A | AA5: A | AB5: =AND(N5,O5,A5<>"census-mixed") | AC5: =IF(AB5,Z5=AA5,"")
A6: census | B6: openssl 3.5.8 default | C6: skb-eval-8352-c5005 | D6: 5005 | E6: 1543 | F6: 771 | G6: 1302 1303 1301 c02c c030 009f cca9 cca8 ccaa c02b c02f 009e c024 c028 006b c023 c027 0067 c00a c014 0039 c009 c013 0033 009d 009c 003d 003c 0035 002f | H6: 0304 0303 | I6: 1 | J6: skb-eval-8352-c5005 | K6: 1543 | L6: 771 | M6: 1443 | N6: TRUE | O6: TRUE | P6: 1302 1303 1301 c02c c030 009f cca9 cca8 ccaa c02b c02f 009e c024 c028 006b c023 c027 0067 c00a c014 0039 c009 c013 0033 009d 009c 003d 003c 0035 002f | Q6: 0304 0303 | R6: violation | S6: violation | T6: =K6=E6 | U6: =L6=F6 | V6: =IF(N6,EXACT(P6,G6),"") | W6: =IF(O6,EXACT(Q6,H6),"") | X6: =J6=C6 | Y6: =IF(R6="unknown","",R6=S6) | Z6: A | AA6: A | AB6: =AND(N6,O6,A6<>"census-mixed") | AC6: =IF(AB6,Z6=AA6,"")
A7: census | B7: openssl 3.5.8 default | C7: skb-eval-8352-c5006 | D7: 5006 | E7: 1543 | F7: 771 | G7: 1302 1303 1301 c02c c030 009f cca9 cca8 ccaa c02b c02f 009e c024 c028 006b c023 c027 0067 c00a c014 0039 c009 c013 0033 009d 009c 003d 003c 0035 002f | H7: 0304 0303 | I7: 1 | J7: skb-eval-8352-c5006 | K7: 1543 | L7: 771 | M7: 1443 | N7: TRUE | O7: TRUE | P7: 1302 1303 1301 c02c c030 009f cca9 cca8 ccaa c02b c02f 009e c024 c028 006b c023 c027 0067 c00a c014 0039 c009 c013 0033 009d 009c 003d 003c 0035 002f | Q7: 0304 0303 | R7: violation | S7: violation | T7: =K7=E7 | U7: =L7=F7 | V7: =IF(N7,EXACT(P7,G7),"") | W7: =IF(O7,EXACT(Q7,H7),"") | X7: =J7=C7 | Y7: =IF(R7="unknown","",R7=S7) | Z7: A | AA7: A | AB7: =AND(N7,O7,A7<>"census-mixed") | AC7: =IF(AB7,Z7=AA7,"")
A8: census | B8: openssl 3.5.8 default | C8: skb-eval-8352-c5007 | D8: 5007 | E8: 1543 | F8: 771 | G8: 1302 1303 1301 c02c c030 009f cca9 cca8 ccaa c02b c02f 009e c024 c028 006b c023 c027 0067 c00a c014 0039 c009 c013 0033 009d 009c 003d 003c 0035 002f | H8: 0304 0303 | I8: 1 | J8: skb-eval-8352-c5007 | K8: 1543 | L8: 771 | M8: 1443 | N8: TRUE | O8: TRUE | P8: 1302 1303 1301 c02c c030 009f cca9 cca8 ccaa c02b c02f 009e c024 c028 006b c023 c027 0067 c00a c014 0039 c009 c013 0033 009d 009c 003d 003c 0035 002f | Q8: 0304 0303 | R8: violation | S8: violation | T8: =K8=E8 | U8: =L8=F8 | V8: =IF(N8,EXACT(P8,G8),"") | W8: =IF(O8,EXACT(Q8,H8),"") | X8: =J8=C8 | Y8: =IF(R8="unknown","",R8=S8) | Z8: A | AA8: A | AB8: =AND(N8,O8,A8<>"census-mixed") | AC8: =IF(AB8,Z8=AA8,"")
A9: census | B9: openssl 3.5.8 default | C9: skb-eval-8352-c5008 | D9: 5008 | E9: 1543 | F9: 771 | G9: 1302 1303 1301 c02c c030 009f cca9 cca8 ccaa c02b c02f 009e c024 c028 006b c023 c027 0067 c00a c014 0039 c009 c013 0033 009d 009c 003d 003c 0035 002f | H9: 0304 0303 | I9: 1 | J9: skb-eval-8352-c5008 | K9: 1543 | L9: 771 | M9: 1443 | N9: TRUE | O9: TRUE | P9: 1302 1303 1301 c02c c030 009f cca9 cca8 ccaa c02b c02f 009e c024 c028 006b c023 c027 0067 c00a c014 0039 c009 c013 0033 009d 009c 003d 003c 0035 002f | Q9: 0304 0303 | R9: violation | S9: violation | T9: =K9=E9 | U9: =L9=F9 | V9: =IF(N9,EXACT(P9,G9),"") | W9: =IF(O9,EXACT(Q9,H9),"") | X9: =J9=C9 | Y9: =IF(R9="unknown","",R9=S9) | Z9: A | AA9: A | AB9: =AND(N9,O9,A9<>"census-mixed") | AC9: =IF(AB9,Z9=AA9,"")
A10: census | B10: openssl 3.5.8 default | C10: skb-eval-8352-c5009 | D10: 5009 | E10: 1543 | F10: 771 | G10: 1302 1303 1301 c02c c030 009f cca9 cca8 ccaa c02b c02f 009e c024 c028 006b c023 c027 0067 c00a c014 0039 c009 c013 0033 009d 009c 003d 003c 0035 002f | H10: 0304 0303 | I10: 1 | J10: skb-eval-8352-c5009 | K10: 1543 | L10: 771 | M10: 1443 | N10: TRUE | O10: TRUE | P10: 1302 1303 1301 c02c c030 009f cca9 cca8 ccaa c02b c02f 009e c024 c028 006b c023 c027 0067 c00a c014 0039 c009 c013 0033 009d 009c 003d 003c 0035 002f | Q10: 0304 0303 | R10: violation | S10: violation | T10: =K10=E10 | U10: =L10=F10 | V10: =IF(N10,EXACT(P10,G10),"") | W10: =IF(O10,EXACT(Q10,H10),"") | X10: =J10=C10 | Y10: =IF(R10="unknown","",R10=S10) | Z10: A | AA10: A | AB10: =AND(N10,O10,A10<>"census-mixed") | AC10: =IF(AB10,Z10=AA10,"")
A11: census | B11: openssl 3.5.8 default | C11: skb-eval-8352-c5010 | D11: 5010 | E11: 1543 | F11: 771 | G11: 1302 1303 1301 c02c c030 009f cca9 cca8 ccaa c02b c02f 009e c024 c028 006b c023 c027 0067 c00a c014 0039 c009 c013 0033 009d 009c 003d 003c 0035 002f | H11: 0304 0303 | I11: 1 | J11: skb-eval-8352-c5010 | K11: 1543 | L11: 771 | M11: 1443 | N11: TRUE | O11: TRUE | P11: 1302 1303 1301 c02c c030 009f cca9 cca8 ccaa c02b c02f 009e c024 c028 006b c023 c027 0067 c00a c014 0039 c009 c013 0033 009d 009c 003d 003c 0035 002f | Q11: 0304 0303 | R11: violation | S11: violation | T11: =K11=E11 | U11: =L11=F11 | V11: =IF(N11,EXACT(P11,G11),"") | W11: =IF(O11,EXACT(Q11,H11),"") | X11: =J11=C11 | Y11: =IF(R11="unknown","",R11=S11) | Z11: A | AA11: A | AB11: =AND(N11,O11,A11<>"census-mixed") | AC11: =IF(AB11,Z11=AA11,"")
A12: census | B12: openssl X25519 only (classical) | C12: skb-eval-8352-c5011 | D12: 5011 | E12: 309 | F12: 771 | G12: 1302 1303 1301 c02c c030 009f cca9 cca8 ccaa c02b c02f 009e c024 c028 006b c023 c027 0067 c00a c014 0039 c009 c013 0033 009d 009c 003d 003c 0035 002f | H12: 0304 0303 | I12: 1 | J12: skb-eval-8352-c5011 | K12: 309 | L12: 771 | M12: 309 | N12: TRUE | O12: TRUE | P12: 1302 1303 1301 c02c c030 009f cca9 cca8 ccaa c02b c02f 009e c024 c028 006b c023 c027 0067 c00a c014 0039 c009 c013 0033 009d 009c 003d 003c 0035 002f | Q12: 0304 0303 | R12: violation | S12: violation | T12: =K12=E12 | U12: =L12=F12 | V12: =IF(N12,EXACT(P12,G12),"") | W12: =IF(O12,EXACT(Q12,H12),"") | X12: =J12=C12 | Y12: =IF(R12="unknown","",R12=S12) | Z12: A | AA12: A | AB12: =AND(N12,O12,A12<>"census-mixed") | AC12: =IF(AB12,Z12=AA12,"")
A13: census | B13: openssl X25519 only (classical) | C13: skb-eval-8352-c5012 | D13: 5012 | E13: 309 | F13: 771 | G13: 1302 1303 1301 c02c c030 009f cca9 cca8 ccaa c02b c02f 009e c024 c028 006b c023 c027 0067 c00a c014 0039 c009 c013 0033 009d 009c 003d 003c 0035 002f | H13: 0304 0303 | I13: 1 | J13: skb-eval-8352-c5012 | K13: 309 | L13: 771 | M13: 309 | N13: TRUE | O13: TRUE | P13: 1302 1303 1301 c02c c030 009f cca9 cca8 ccaa c02b c02f 009e c024 c028 006b c023 c027 0067 c00a c014 0039 c009 c013 0033 009d 009c 003d 003c 0035 002f | Q13: 0304 0303 | R13: violation | S13: violation | T13: =K13=E13 | U13: =L13=F13 | V13: =IF(N13,EXACT(P13,G13),"") | W13: =IF(O13,EXACT(Q13,H13),"") | X13: =J13=C13 | Y13: =IF(R13="unknown","",R13=S13) | Z13: A | AA13: A | AB13: =AND(N13,O13,A13<>"census-mixed") | AC13: =IF(AB13,Z13=AA13,"")
... A81: census | B81: openssl MLKEM1024 (pure PQ) | C81: skb-eval-8352-c5080 | D81: 5080 | E81: 1837 | F81: 771 | G81: 1302 1303 1301 c02c c030 009f cca9 cca8 ccaa c02b c02f 009e c024 c028 006b c023 c027 0067 c00a c014 0039 c009 c013 0033 009d 009c 003d 003c 0035 002f | H81: 0304 0303 | I81: 1 | J81: skb-eval-8352-c5080 | K81: 1837 | L81: 771 | M81: 1443 | N81: TRUE | O81: TRUE | P81: 1302 1303 1301 c02c c030 009f cca9 cca8 ccaa c02b c02f 009e c024 c028 006b c023 c027 0067 c00a c014 0039 c009 c013 0033 009d 009c 003d 003c 0035 002f | Q81: 0304 0303 | R81: violation | S81: violation | T81: =K81=E81 | U81: =L81=F81 | V81: =IF(N81,EXACT(P81,G81),"") | W81: =IF(O81,EXACT(Q81,H81),"") | X81: =J81=C81 | Y81: =IF(R81="unknown","",R81=S81) | Z81: A | AA81: A | AB81: =AND(N81,O81,A81<>"census-mixed") | AC81: =IF(AB81,Z81=AA81,"")
A82: census | B82: openssl TLS 1.2 only | C82: skb-eval-8352-c5081 | D82: 5081 | E82: 210 | F82: 771 | G82: c02c c030 009f cca9 cca8 ccaa c02b c02f 009e c024 c028 006b c023 c027 0067 c00a c014 0039 c009 c013 0033 009d 009c 003d 003c 0035 002f | I82: 1 | J82: skb-eval-8352-c5081 | K82: 210 | L82: 771 | M82: 210 | N82: TRUE | O82: TRUE | P82: c02c c030 009f cca9 cca8 ccaa c02b c02f 009e c024 c028 006b c023 c027 0067 c00a c014 0039 c009 c013 0033 009d 009c 003d 003c 0035 002f | R82: violation | S82: violation | T82: =K82=E82 | U82: =L82=F82 | V82: =IF(N82,EXACT(P82,G82),"") | W82: =IF(O82,EXACT(Q82,H82),"") | X82: =J82=C82 | Y82: =IF(R82="unknown","",R82=S82) | Z82: A | AA82: A | AB82: =AND(N82,O82,A82<>"census-mixed") | AC82: =IF(AB82,Z82=AA82,"")
A83: census | B83: openssl TLS 1.2 only | C83: skb-eval-8352-c5082 | D83: 5082 | E83: 210 | F83: 771 | G83: c02c c030 009f cca9 cca8 ccaa c02b c02f 009e c024 c028 006b c023 c027 0067 c00a c014 0039 c009 c013 0033 009d 009c 003d 003c 0035 002f | I83: 1 | J83: skb-eval-8352-c5082 | K83: 210 | L83: 771 | M83: 210 | N83: TRUE | O83: TRUE | P83: c02c c030 009f cca9 cca8 ccaa c02b c02f 009e c024 c028 006b c023 c027 0067 c00a c014 0039 c009 c013 0033 009d 009c 003d 003c 0035 002f | R83: violation | S83: violation | T83: =K83=E83 | U83: =L83=F83 | V83: =IF(N83,EXACT(P83,G83),"") | W83: =IF(O83,EXACT(Q83,H83),"") | X83: =J83=C83 | Y83: =IF(R83="unknown","",R83=S83) | Z83: A | AA83: A | AB83: =AND(N83,O83,A83<>"census-mixed") | AC83: =IF(AB83,Z83=AA83,"")
A84: census | B84: openssl TLS 1.2 only | C84: skb-eval-8352-c5083 | D84: 5083 | E84: 210 | F84: 771 | G84: c02c c030 009f cca9 cca8 ccaa c02b c02f 009e c024 c028 006b c023 c027 0067 c00a c014 0039 c009 c013 0033 009d 009c 003d 003c 0035 002f | I84: 1 | J84: skb-eval-8352-c5083 | K84: 210 | L84: 771 | M84: 210 | N84: TRUE | O84: TRUE | P84: c02c c030 009f cca9 cca8 ccaa c02b c02f 009e c024 c028 006b c023 c027 0067 c00a c014 0039 c009 c013 0033 009d 009c 003d 003c 0035 002f | R84: violation | S84: violation | T84: =K84=E84 | U84: =L84=F84 | V84: =IF(N84,EXACT(P84,G84),"") | W84: =IF(O84,EXACT(Q84,H84),"") | X84: =J84=C84 | Y84: =IF(R84="unknown","",R84=S84) | Z84: A | AA84: A | AB84: =AND(N84,O84,A84<>"census-mixed") | AC84: =IF(AB84,Z84=AA84,"")
A85: census | B85: openssl TLS 1.2 only | C85: skb-eval-8352-c5084 | D85: 5084 | E85: 210 | F85: 771 | G85: c02c c030 009f cca9 cca8 ccaa c02b c02f 009e c024 c028 006b c023 c027 0067 c00a c014 0039 c009 c013 0033 009d 009c 003d 003c 0035 002f | I85: 1 | J85: skb-eval-8352-c5084 | K85: 210 | L85: 771 | M85: 210 | N85: TRUE | O85: TRUE | P85: c02c c030 009f cca9 cca8 ccaa c02b c02f 009e c024 c028 006b c023 c027 0067 c00a c014 0039 c009 c013 0033 009d 009c 003d 003c 0035 002f | R85: violation | S85: violation | T85: =K85=E85 | U85: =L85=F85 | V85: =IF(N85,EXACT(P85,G85),"") | W85: =IF(O85,EXACT(Q85,H85),"") | X85: =J85=C85 | Y85: =IF(R85="unknown","",R85=S85) | Z85: A | AA85: A | AB85: =AND(N85,O85,A85<>"census-mixed") | AC85: =IF(AB85,Z85=AA85,"")
A86: census | B86: openssl TLS 1.2 only | C86: skb-eval-8352-c5085 | D86: 5085 | E86: 210 | F86: 771 | G86: c02c c030 009f cca9 cca8 ccaa c02b c02f 009e c024 c028 006b c023 c027 0067 c00a c014 0039 c009 c013 0033 009d 009c 003d 003c 0035 002f | I86: 1 | J86: skb-eval-8352-c5085 | K86: 210 | L86: 771 | M86: 210 | N86: TRUE | O86: TRUE | P86: c02c c030 009f cca9 cca8 ccaa c02b c02f 009e c024 c028 006b c023 c027 0067 c00a c014 0039 c009 c013 0033 009d 009c 003d 003c 0035 002f | R86: violation | S86: violation | T86: =K86=E86 | U86: =L86=F86 | V86: =IF(N86,EXACT(P86,G86),"") | W86: =IF(O86,EXACT(Q86,H86),"") | X86: =J86=C86 | Y86: =IF(R86="unknown","",R86=S86) | Z86: A | AA86: A | AB86: =AND(N86,O86,A86<>"census-mixed") | AC86: =IF(AB86,Z86=AA86,"")
A87: census | B87: openssl TLS 1.2 only | C87: skb-eval-8352-c5086 | D87: 5086 | E87: 210 | F87: 771 | G87: c02c c030 009f cca9 cca8 ccaa c02b c02f 009e c024 c028 006b c023 c027 0067 c00a c014 0039 c009 c013 0033 009d 009c 003d 003c 0035 002f | I87: 1 | J87: skb-eval-8352-c5086 | K87: 210 | L87: 771 | M87: 210 | N87: TRUE | O87: TRUE | P87: c02c c030 009f cca9 cca8 ccaa c02b c02f 009e c024 c028 006b c023 c027 0067 c00a c014 0039 c009 c013 0033 009d 009c 003d 003c 0035 002f | R87: violation | S87: violation | T87: =K87=E87 | U87: =L87=F87 | V87: =IF(N87,EXACT(P87,G87),"") | W87: =IF(O87,EXACT(Q87,H87),"") | X87: =J87=C87 | Y87: =IF(R87="unknown","",R87=S87) | Z87: A | AA87: A | AB87: =AND(N87,O87,A87<>"census-mixed") | AC87: =IF(AB87,Z87=AA87,"")
A88: census | B88: openssl TLS 1.2 only | C88: skb-eval-8352-c5087 | D88: 5087 | E88: 210 | F88: 771 | G88: c02c c030 009f cca9 cca8 ccaa c02b c02f 009e c024 c028 006b c023 c027 0067 c00a c014 0039 c009 c013 0033 009d 009c 003d 003c 0035 002f | I88: 1 | J88: skb-eval-8352-c5087 | K88: 210 | L88: 771 | M88: 210 | N88: TRUE | O88: TRUE | P88: c02c c030 009f cca9 cca8 ccaa c02b c02f 009e c024 c028 006b c023 c027 0067 c00a c014 0039 c009 c013 0033 009d 009c 003d 003c 0035 002f | R88: violation | S88: violation | T88: =K88=E88 | U88: =L88=F88 | V88: =IF(N88,EXACT(P88,G88),"") | W88: =IF(O88,EXACT(Q88,H88),"") | X88: =J88=C88 | Y88: =IF(R88="unknown","",R88=S88) | Z88: A | AA88: A | AB88: =AND(N88,O88,A88<>"census-mixed") | AC88: =IF(AB88,Z88=AA88,"")
A89: census | B89: openssl TLS 1.2 only | C89: skb-eval-8352-c5088 | D89: 5088 | E89: 210 | F89: 771 | G89: c02c c030 009f cca9 cca8 ccaa c02b c02f 009e c024 c028 006b c023 c027 0067 c00a c014 0039 c009 c013 0033 009d 009c 003d 003c 0035 002f | I89: 1 | J89: skb-eval-8352-c5088 | K89: 210 | L89: 771 | M89: 210 | N89: TRUE | O89: TRUE | P89: c02c c030 009f cca9 cca8 ccaa c02b c02f 009e c024 c028 006b c023 c027 0067 c00a c014 0039 c009 c013 0033 009d 009c 003d 003c 0035 002f | R89: violation | S89: violation | T89: =K89=E89 | U89: =L89=F89 | V89: =IF(N89,EXACT(P89,G89),"") | W89: =IF(O89,EXACT(Q89,H89),"") | X89: =J89=C89 | Y89: =IF(R89="unknown","",R89=S89) | Z89: A | AA89: A | AB89: =AND(N89,O89,A89<>"census-mixed") | AC89: =IF(AB89,Z89=AA89,"")
A90: census | B90: openssl TLS 1.2 only | C90: skb-eval-8352-c5089 | D90: 5089 | E90: 210 | F90: 771 | G90: c02c c030 009f cca9 cca8 ccaa c02b c02f 009e c024 c028 006b c023 c027 0067 c00a c014 0039 c009 c013 0033 009d 009c 003d 003c 0035 002f | I90: 1 | J90: skb-eval-8352-c5089 | K90: 210 | L90: 771 | M90: 210 | N90: TRUE | O90: TRUE | P90: c02c c030 009f cca9 cca8 ccaa c02b c02f 009e c024 c028 006b c023 c027 0067 c00a c014 0039 c009 c013 0033 009d 009c 003d 003c 0035 002f | R90: violation | S90: violation | T90: =K90=E90 | U90: =L90=F90 | V90: =IF(N90,EXACT(P90,G90),"") | W90: =IF(O90,EXACT(Q90,H90),"") | X90: =J90=C90 | Y90: =IF(R90="unknown","",R90=S90) | Z90: A | AA90: A | AB90: =AND(N90,O90,A90<>"census-mixed") | AC90: =IF(AB90,Z90=AA90,"")
A91: census | B91: openssl TLS 1.2 only | C91: skb-eval-8352-c5090 | D91: 5090 | E91: 210 | F91: 771 | G91: c02c c030 009f cca9 cca8 ccaa c02b c02f 009e c024 c028 006b c023 c027 0067 c00a c014 0039 c009 c013 0033 009d 009c 003d 003c 0035 002f | I91: 1 | J91: skb-eval-8352-c5090 | K91: 210 | L91: 771 | M91: 210 | N91: TRUE | O91: TRUE | P91: c02c c030 009f cca9 cca8 ccaa c02b c02f 009e c024 c028 006b c023 c027 0067 c00a c014 0039 c009 c013 0033 009d 009c 003d 003c 0035 002f | R91: violation | S91: violation | T91: =K91=E91 | U91: =L91=F91 | V91: =IF(N91,EXACT(P91,G91),"") | W91: =IF(O91,EXACT(Q91,H91),"") | X91: =J91=C91 | Y91: =IF(R91="unknown","",R91=S91) | Z91: A | AA91: A | AB91: =AND(N91,O91,A91<>"census-mixed") | AC91: =IF(AB91,Z91=AA91,"")
A92: census | B92: curl 8.22 (OpenSSL 3.5.8) | C92: skb-eval-8352-c5091 | D92: 5091 | E92: 1561 | F92: 771 | G92: 1302 1303 1301 c02c c030 009f cca9 cca8 ccaa c02b c02f 009e c024 c028 006b c023 c027 0067 c00a c014 0039 c009 c013 0033 009d 009c 003d 003c 0035 002f | H92: 0304 0303 | I92: 1 | J92: skb-eval-8352-c5091 | K92: 1561 | L92: 771 | M92: 1443 | N92: TRUE | O92: TRUE | P92: 1302 1303 1301 c02c c030 009f cca9 cca8 ccaa c02b c02f 009e c024 c028 006b c023 c027 0067 c00a c014 0039 c009 c013 0033 009d 009c 003d 003c 0035 002f | Q92: 0304 0303 | R92: violation | S92: violation | T92: =K92=E92 | U92: =L92=F92 | V92: =IF(N92,EXACT(P92,G92),"") | W92: =IF(O92,EXACT(Q92,H92),"") | X92: =J92=C92 | Y92: =IF(R92="unknown","",R92=S92) | Z92: A | AA92: A | AB92: =AND(N92,O92,A92<>"census-mixed") | AC92: =IF(AB92,Z92=AA92,"")
A93: census | B93: curl 8.22 (OpenSSL 3.5.8) | C93: skb-eval-8352-c5092 | D93: 5092 | E93: 1561 | F93: 771 | G93: 1302 1303 1301 c02c c030 009f cca9 cca8 ccaa c02b c02f 009e c024 c028 006b c023 c027 0067 c00a c014 0039 c009 c013 0033 009d 009c 003d 003c 0035 002f | H93: 0304 0303 | I93: 1 | J93: skb-eval-8352-c5092 | K93: 1561 | L93: 771 | M93: 1443 | N93: TRUE | O93: TRUE | P93: 1302 1303 1301 c02c c030 009f cca9 cca8 ccaa c02b c02f 009e c024 c028 006b c023 c027 0067 c00a c014 0039 c009 c013 0033 009d 009c 003d 003c 0035 002f | Q93: 0304 0303 | R93: violation | S93: violation | T93: =K93=E93 | U93: =L93=F93 | V93: =IF(N93,EXACT(P93,G93),"") | W93: =IF(O93,EXACT(Q93,H93),"") | X93: =J93=C93 | Y93: =IF(R93="unknown","",R93=S93) | Z93: A | AA93: A | AB93: =AND(N93,O93,A93<>"census-mixed") | AC93: =IF(AB93,Z93=AA93,"")
A94: census | B94: curl 8.22 (OpenSSL 3.5.8) | C94: skb-eval-8352-c5093 | D94: 5093 | E94: 1561 | F94: 771 | G94: 1302 1303 1301 c02c c030 009f cca9 cca8 ccaa c02b c02f 009e c024 c028 006b c023 c027 0067 c00a c014 0039 c009 c013 0033 009d 009c 003d 003c 0035 002f | H94: 0304 0303 | I94: 1 | J94: skb-eval-8352-c5093 | K94: 1561 | L94: 771 | M94: 1443 | N94: TRUE | O94: TRUE | P94: 1302 1303 1301 c02c c030 009f cca9 cca8 ccaa c02b c02f 009e c024 c028 006b c023 c027 0067 c00a c014 0039 c009 c013 0033 009d 009c 003d 003c 0035 002f | Q94: 0304 0303 | R94: violation | S94: violation | T94: =K94=E94 | U94: =L94=F94 | V94: =IF(N94,EXACT(P94,G94),"") | W94: =IF(O94,EXACT(Q94,H94),"") | X94: =J94=C94 | Y94: =IF(R94="unknown","",R94=S94) | Z94: A | AA94: A | AB94: =AND(N94,O94,A94<>"census-mixed") | AC94: =IF(AB94,Z94=AA94,"")
A95: census | B95: curl 8.22 (OpenSSL 3.5.8) | C95: skb-eval-8352-c5094 | D95: 5094 | E95: 1561 | F95: 771 | G95: 1302 1303 1301 c02c c030 009f cca9 cca8 ccaa c02b c02f 009e c024 c028 006b c023 c027 0067 c00a c014 0039 c009 c013 0033 009d 009c 003d 003c 0035 002f | H95: 0304 0303 | I95: 1 | J95: skb-eval-8352-c5094 | K95: 1561 | L95: 771 | M95: 1443 | N95: TRUE | O95: TRUE | P95: 1302 1303 1301 c02c c030 009f cca9 cca8 ccaa c02b c02f 009e c024 c028 006b c023 c027 0067 c00a c014 0039 c009 c013 0033 009d 009c 003d 003c 0035 002f | Q95: 0304 0303 | R95: violation | S95: violation | T95: =K95=E95 | U95: =L95=F95 | V95: =IF(N95,EXACT(P95,G95),"") | W95: =IF(O95,EXACT(Q95,H95),"") | X95: =J95=C95 | Y95: =IF(R95="unknown","",R95=S95) | Z95: A | AA95: A | AB95: =AND(N95,O95,A95<>"census-mixed") | AC95: =IF(AB95,Z95=AA95,"")
A96: census | B96: curl 8.22 (OpenSSL 3.5.8) | C96: skb-eval-8352-c5095 | D96: 5095 | E96: 1561 | F96: 771 | G96: 1302 1303 1301 c02c c030 009f cca9 cca8 ccaa c02b c02f 009e c024 c028 006b c023 c027 0067 c00a c014 0039 c009 c013 0033 009d 009c 003d 003c 0035 002f | H96: 0304 0303 | I96: 1 | J96: skb-eval-8352-c5095 | K96: 1561 | L96: 771 | M96: 1443 | N96: TRUE | O96: TRUE | P96: 1302 1303 1301 c02c c030 009f cca9 cca8 ccaa c02b c02f 009e c024 c028 006b c023 c027 0067 c00a c014 0039 c009 c013 0033 009d 009c 003d 003c 0035 002f | Q96: 0304 0303 | R96: violation | S96: violation | T96: =K96=E96 | U96: =L96=F96 | V96: =IF(N96,EXACT(P96,G96),"") | W96: =IF(O96,EXACT(Q96,H96),"") | X96: =J96=C96 | Y96: =IF(R96="unknown","",R96=S96) | Z96: A | AA96: A | AB96: =AND(N96,O96,A96<>"census-mixed") | AC96: =IF(AB96,Z96=AA96,"")
A97: census | B97: curl 8.22 (OpenSSL 3.5.8) | C97: skb-eval-8352-c5096 | D97: 5096 | E97: 1561 | F97: 771 | G97: 1302 1303 1301 c02c c030 009f cca9 cca8 ccaa c02b c02f 009e c024 c028 006b c023 c027 0067 c00a c014 0039 c009 c013 0033 009d 009c 003d 003c 0035 002f | H97: 0304 0303 | I97: 1 | J97: skb-eval-8352-c5096 | K97: 1561 | L97: 771 | M97: 1443 | N97: TRUE | O97: TRUE | P97: 1302 1303 1301 c02c c030 009f cca9 cca8 ccaa c02b c02f 009e c024 c028 006b c023 c027 0067 c00a c014 0039 c009 c013 0033 009d 009c 003d 003c 0035 002f | Q97: 0304 0303 | R97: violation | S97: violation | T97: =K97=E97 | U97: =L97=F97 | V97: =IF(N97,EXACT(P97,G97),"") | W97: =IF(O97,EXACT(Q97,H97),"") | X97: =J97=C97 | Y97: =IF(R97="unknown","",R97=S97) | Z97: A | AA97: A | AB97: =AND(N97,O97,A97<>"census-mixed") | AC97: =IF(AB97,Z97=AA97,"")
A98: census | B98: curl 8.22 (OpenSSL 3.5.8) | C98: skb-eval-8352-c5097 | D98: 5097 | E98: 1561 | F98: 771 | G98: 1302 1303 1301 c02c c030 009f cca9 cca8 ccaa c02b c02f 009e c024 c028 006b c023 c027 0067 c00a c014 0039 c009 c013 0033 009d 009c 003d 003c 0035 002f | H98: 0304 0303 | I98: 1 | J98: skb-eval-8352-c5097 | K98: 1561 | L98: 771 | M98: 1443 | N98: TRUE | O98: TRUE | P98: 1302 1303 1301 c02c c030 009f cca9 cca8 ccaa c02b c02f 009e c024 c028 006b c023 c027 0067 c00a c014 0039 c009 c013 0033 009d 009c 003d 003c 0035 002f | Q98: 0304 0303 | R98: violation | S98: violation | T98: =K98=E98 | U98: =L98=F98 | V98: =IF(N98,EXACT(P98,G98),"") | W98: =IF(O98,EXACT(Q98,H98),"") | X98: =J98=C98 | Y98: =IF(R98="unknown","",R98=S98) | Z98: A | AA98: A | AB98: =AND(N98,O98,A98<>"census-mixed") | AC98: =IF(AB98,Z98=AA98,"")
A99: census | B99: curl 8.22 (OpenSSL 3.5.8) | C99: skb-eval-8352-c5098 | D99: 5098 | E99: 1561 | F99: 771 | G99: 1302 1303 1301 c02c c030 009f cca9 cca8 ccaa c02b c02f 009e c024 c028 006b c023 c027 0067 c00a c014 0039 c009 c013 0033 009d 009c 003d 003c 0035 002f | H99: 0304 0303 | I99: 1 | J99: skb-eval-8352-c5098 | K99: 1561 | L99: 771 | M99: 1443 | N99: TRUE | O99: TRUE | P99: 1302 1303 1301 c02c c030 009f cca9 cca8 ccaa c02b c02f 009e c024 c028 006b c023 c027 0067 c00a c014 0039 c009 c013 0033 009d 009c 003d 003c 0035 002f | Q99: 0304 0303 | R99: violation | S99: violation | T99: =K99=E99 | U99: =L99=F99 | V99: =IF(N99,EXACT(P99,G99),"") | W99: =IF(O99,EXACT(Q99,H99),"") | X99: =J99=C99 | Y99: =IF(R99="unknown","",R99=S99) | Z99: A | AA99: A | AB99: =AND(N99,O99,A99<>"census-mixed") | AC99: =IF(AB99,Z99=AA99,"")
A100: census | B100: curl 8.22 (OpenSSL 3.5.8) | C100: skb-eval-8352-c5099 | D100: 5099 | E100: 1561 | F100: 771 | G100: 1302 1303 1301 c02c c030 009f cca9 cca8 ccaa c02b c02f 009e c024 c028 006b c023 c027 0067 c00a c014 0039 c009 c013 0033 009d 009c 003d 003c 0035 002f | H100: 0304 0303 | I100: 1 | J100: skb-eval-8352-c5099 | K100: 1561 | L100: 771 | M100: 1443 | N100: TRUE | O100: TRUE | P100: 1302 1303 1301 c02c c030 009f cca9 cca8 ccaa c02b c02f 009e c024 c028 006b c023 c027 0067 c00a c014 0039 c009 c013 0033 009d 009c 003d 003c 0035 002f | Q100: 0304 0303 | R100: violation | S100: violation | T100: =K100=E100 | U100: =L100=F100 | V100: =IF(N100,EXACT(P100,G100),"") | W100: =IF(O100,EXACT(Q100,H100),"") | X100: =J100=C100 | Y100: =IF(R100="unknown","",R100=S100) | Z100: A | AA100: A | AB100: =AND(N100,O100,A100<>"census-mixed") | AC100: =IF(AB100,Z100=AA100,"")
A101: census | B101: curl 8.22 (OpenSSL 3.5.8) | C101: skb-eval-8352-c5100 | D101: 5100 | E101: 1561 | F101: 771 | G101: 1302 1303 1301 c02c c030 009f cca9 cca8 ccaa c02b c02f 009e c024 c028 006b c023 c027 0067 c00a c014 0039 c009 c013 0033 009d 009c 003d 003c 0035 002f | H101: 0304 0303 | I101: 1 | J101: skb-eval-8352-c5100 | K101: 1561 | L101: 771 | M101: 1443 | N101: TRUE | O101: TRUE | P101: 1302 1303 1301 c02c c030 009f cca9 cca8 ccaa c02b c02f 009e c024 c028 006b c023 c027 0067 c00a c014 0039 c009 c013 0033 009d 009c 003d 003c 0035 002f | Q101: 0304 0303 | R101: violation | S101: violation | T101: =K101=E101 | U101: =L101=F101 | V101: =IF(N101,EXACT(P101,G101),"") | W101: =IF(O101,EXACT(Q101,H101),"") | X101: =J101=C101 | Y101: =IF(R101="unknown","",R101=S101) | Z101: A | AA101: A | AB101: =AND(N101,O101,A101<>"census-mixed") | AC101: =IF(AB101,Z101=AA101,"")
A102: census | B102: python 3.14 urllib (OpenSSL 3.5.8) | C102: skb-eval-8352-c5101 | D102: 5101 | E102: 1517 | F102: 771 | G102: 1302 1303 1301 c02c c030 c02b c02f cca9 cca8 c024 c028 c023 c027 009f 009e 006b 0067 | H102: 0304 0303 | I102: 1 | J102: skb-eval-8352-c5101 | K102: 1517 | L102: 771 | M102: 1443 | N102: TRUE | O102: TRUE | P102: 1302 1303 1301 c02c c030 c02b c02f cca9 cca8 c024 c028 c023 c027 009f 009e 006b 0067 | Q102: 0304 0303 | R102: violation | S102: violation | T102: =K102=E102 | U102: =L102=F102 | V102: =IF(N102,EXACT(P102,G102),"") | W102: =IF(O102,EXACT(Q102,H102),"") | X102: =J102=C102 | Y102: =IF(R102="unknown","",R102=S102) | Z102: A | AA102: A | AB102: =AND(N102,O102,A102<>"census-mixed") | AC102: =IF(AB102,Z102=AA102,"")
A103: census | B103: python 3.14 urllib (OpenSSL 3.5.8) | C103: skb-eval-8352-c5102 | D103: 5102 | E103: 1517 | F103: 771 | G103: 1302 1303 1301 c02c c030 c02b c02f cca9 cca8 c024 c028 c023 c027 009f 009e 006b 0067 | H103: 0304 0303 | I103: 1 | J103: skb-eval-8352-c5102 | K103: 1517 | L103: 771 | M103: 1443 | N103: TRUE | O103: TRUE | P103: 1302 1303 1301 c02c c030 c02b c02f cca9 cca8 c024 c028 c023 c027 009f 009e 006b 0067 | Q103: 0304 0303 | R103: violation | S103: violation | T103: =K103=E103 | U103: =L103=F103 | V103: =IF(N103,EXACT(P103,G103),"") | W103: =IF(O103,EXACT(Q103,H103),"") | X103: =J103=C103 | Y103: =IF(R103="unknown","",R103=S103) | Z103: A | AA103: A | AB103: =AND(N103,O103,A103<>"census-mixed") | AC103: =IF(AB103,Z103=AA103,"")
... A141: census | B141: browser chrome116 | C141: skb-eval-8352-c5140 | D141: 5140 | E141: 512 | F141: 771 | G141: 1a1a 1301 1302 1303 c02b c02f c02c c030 cca9 cca8 c013 c014 009c 009d 002f 0035 | H141: dada 0304 0303 | I141: 1 | J141: skb-eval-8352-c5140 | K141: 512 | L141: 771 | M141: 512 | N141: TRUE | O141: TRUE | P141: 1a1a 1301 1302 1303 c02b c02f c02c c030 cca9 cca8 c013 c014 009c 009d 002f 0035 | Q141: dada 0304 0303 | R141: violation | S141: violation | T141: =K141=E141 | U141: =L141=F141 | V141: =IF(N141,EXACT(P141,G141),"") | W141: =IF(O141,EXACT(Q141,H141),"") | X141: =J141=C141 | Y141: =IF(R141="unknown","",R141=S141) | Z141: A | AA141: A | AB141: =AND(N141,O141,A141<>"census-mixed") | AC141: =IF(AB141,Z141=AA141,"")
A142: census | B142: browser chrome124 | C142: skb-eval-8352-c5141 | D142: 5141 | E142: 1784 | F142: 771 | G142: eaea 1301 1302 1303 c02b c02f c02c c030 cca9 cca8 c013 c014 009c 009d 002f 0035 | H142: 0a0a 0304 0303 | I142: 1 | J142: skb-eval-8352-c5141 | K142: 1784 | L142: 771 | M142: 1443 | N142: TRUE | O142: FALSE | P142: eaea 1301 1302 1303 c02b c02f c02c c030 cca9 cca8 c013 c014 009c 009d 002f 0035 | R142: violation | S142: violation | T142: =K142=E142 | U142: =L142=F142 | V142: =IF(N142,EXACT(P142,G142),"") | W142: =IF(O142,EXACT(Q142,H142),"") | X142: =J142=C142 | Y142: =IF(R142="unknown","",R142=S142) | Z142: A | AA142: A | AB142: =AND(N142,O142,A142<>"census-mixed") | AC142: =IF(AB142,Z142=AA142,"")
A143: census | B143: browser chrome124 | C143: skb-eval-8352-c5142 | D143: 5142 | E143: 1784 | F143: 771 | G143: caca 1301 1302 1303 c02b c02f c02c c030 cca9 cca8 c013 c014 009c 009d 002f 0035 | H143: dada 0304 0303 | I143: 1 | J143: skb-eval-8352-c5142 | K143: 1784 | L143: 771 | M143: 1443 | N143: TRUE | O143: FALSE | P143: caca 1301 1302 1303 c02b c02f c02c c030 cca9 cca8 c013 c014 009c 009d 002f 0035 | R143: violation | S143: violation | T143: =K143=E143 | U143: =L143=F143 | V143: =IF(N143,EXACT(P143,G143),"") | W143: =IF(O143,EXACT(Q143,H143),"") | X143: =J143=C143 | Y143: =IF(R143="unknown","",R143=S143) | Z143: A | AA143: A | AB143: =AND(N143,O143,A143<>"census-mixed") | AC143: =IF(AB143,Z143=AA143,"")
A144: census | B144: browser chrome124 | C144: skb-eval-8352-c5143 | D144: 5143 | E144: 1720 | F144: 771 | G144: 2a2a 1301 1302 1303 c02b c02f c02c c030 cca9 cca8 c013 c014 009c 009d 002f 0035 | H144: 2a2a 0304 0303 | I144: 1 | J144: skb-eval-8352-c5143 | K144: 1720 | L144: 771 | M144: 1443 | N144: TRUE | O144: TRUE | P144: 2a2a 1301 1302 1303 c02b c02f c02c c030 cca9 cca8 c013 c014 009c 009d 002f 0035 | Q144: 2a2a 0304 0303 | R144: violation | S144: violation | T144: =K144=E144 | U144: =L144=F144 | V144: =IF(N144,EXACT(P144,G144),"") | W144: =IF(O144,EXACT(Q144,H144),"") | X144: =J144=C144 | Y144: =IF(R144="unknown","",R144=S144) | Z144: A | AA144: A | AB144: =AND(N144,O144,A144<>"census-mixed") | AC144: =IF(AB144,Z144=AA144,"")
...

Sheet Exp3_fuzz
A1: i | B1: Kind | C1: From | D1: Bytes sent | E1: Bytes received | F1: Events | G1: Events with ciphers_seen | H1: Events with versions_seen | I1: False complete fields | K1: Run | L1: Value
A2: 0 | B2: original | C2: openssl X25519 only (classical) | D2: 314 | E2: 314 | F2: 1 | G2: 1 | H2: 1 | I2: 0 | K2: skbouncer alive at end | L2: TRUE
A3: 1 | B3: original | C3: openssl 3.5.8 default | D3: 1548 | E3: 1548 | F3: 1 | G3: 1 | H3: 1 | I3: 0 | K3: skb_tc attached at end | L3: 1
A4: 2 | B4: original | C4: openssl TLS 1.2 only | D4: 215 | E4: 215 | F4: 1 | G4: 1 | H4: 1 | I4: 0 | K4: Detected | L4: 4693
A5: 3 | B5: original | C5: browser chrome150 | D5: 1763 | E5: 1763 | F5: 1 | G5: 1 | H5: 1 | I5: 0 | K5: Too short to classify | L5: 8
A6: 4 | B6: original | C6: browser firefox147 | D6: 1901 | E6: 1901 | F6: 1 | G6: 1 | H6: 0 | I6: 0
A7: 5 | B7: flip | C7: openssl 3.5.8 default | D7: 1548 | E7: 1548 | F7: 1 | G7: 1 | H7: 1 | I7: 0
A8: 6 | B8: truncate | C8: browser chrome150 | D8: 968 | E8: 968 | F8: 1 | G8: 1 | H8: 1 | I8: 0
A9: 7 | B9: length | C9: browser chrome150 | D9: 1763 | E9: 1763 | F9: 0 | G9: 0 | H9: 0 | I9: 0
A10: 8 | B10: insert | C10: browser chrome150 | D10: 1764 | E10: 1764 | F10: 1 | G10: 1 | H10: 1 | I10: 0
A11: 9 | B11: flip | C11: browser chrome150 | D11: 1763 | E11: 1763 | F11: 1 | G11: 1 | H11: 1 | I11: 0
A12: 10 | B12: truncate | C12: browser firefox147 | D12: 19 | E12: 19 | F12: 1 | G12: 0 | H12: 0 | I12: 0
A13: 11 | B13: length | C13: browser chrome150 | D13: 1763 | E13: 1763 | F13: 1 | G13: 1 | H13: 1 | I13: 0
A14: 12 | B14: insert | C14: openssl 3.5.8 default | D14: 1564 | E14: 1564 | F14: 1 | G14: 1 | H14: 1 | I14: 0
A15: 13 | B15: flip | C15: openssl 3.5.8 default | D15: 1548 | E15: 1548 | F15: 1 | G15: 1 | H15: 1 | I15: 0
A16: 14 | B16: truncate | C16: browser firefox147 | D16: 865 | E16: 865 | F16: 1 | G16: 1 | H16: 0 | I16: 0
A17: 15 | B17: length | C17: browser firefox147 | D17: 1901 | E17: 1901 | F17: 1 | G17: 0 | H17: 0 | I17: 0
... A5006: 5004 | B5006: insert | C5006: openssl TLS 1.2 only | D5006: 231 | E5006: 231 | F5006: 1 | G5006: 1 | H5006: 1 | I5006: 0

Sheet Exp4
A1: Arm | B1: MTU | C1: Timestamps | D1: MSS | E1: Client | F1: Post-quantum | G1: Rep | H1: Server record_len | I1: Event record_len | J1: captured_len | K1: Split (truth) | L1: Flagged split | M1: ciphers_seen | N1: versions_seen | O1: Verdict | P1: Decidable
A2: 1280-off | B2: 1280 | C2: off | D2: 1240 | E2: openssl 3.5.8 default | F2: TRUE | G2: 1 | H2: 1543 | I2: 1543 | J2: 1235 | K2: =H2+5>D2 | L2: =J2<I2 | M2: TRUE | N2: TRUE | O2: allow | P2: =O2<>"unknown"
A3: 1280-off | B3: 1280 | C3: off | D3: 1240 | E3: openssl 3.5.8 default | F3: TRUE | G3: 2 | H3: 1543 | I3: 1543 | J3: 1235 | K3: =H3+5>D3 | L3: =J3<I3 | M3: TRUE | N3: TRUE | O3: allow | P3: =O3<>"unknown"
A4: 1280-off | B4: 1280 | C4: off | D4: 1240 | E4: openssl 3.5.8 default | F4: TRUE | G4: 3 | H4: 1543 | I4: 1543 | J4: 1235 | K4: =H4+5>D4 | L4: =J4<I4 | M4: TRUE | N4: TRUE | O4: allow | P4: =O4<>"unknown"
A5: 1280-off | B5: 1280 | C5: off | D5: 1240 | E5: openssl 3.5.8 default | F5: TRUE | G5: 4 | H5: 1543 | I5: 1543 | J5: 1235 | K5: =H5+5>D5 | L5: =J5<I5 | M5: TRUE | N5: TRUE | O5: allow | P5: =O5<>"unknown"
A6: 1280-off | B6: 1280 | C6: off | D6: 1240 | E6: openssl 3.5.8 default | F6: TRUE | G6: 5 | H6: 1543 | I6: 1543 | J6: 1235 | K6: =H6+5>D6 | L6: =J6<I6 | M6: TRUE | N6: TRUE | O6: allow | P6: =O6<>"unknown"
A7: 1280-off | B7: 1280 | C7: off | D7: 1240 | E7: openssl X25519 only (classical) | F7: FALSE | G7: 1 | H7: 309 | I7: 309 | J7: 309 | K7: =H7+5>D7 | L7: =J7<I7 | M7: TRUE | N7: TRUE | O7: allow | P7: =O7<>"unknown"
A8: 1280-off | B8: 1280 | C8: off | D8: 1240 | E8: openssl X25519 only (classical) | F8: FALSE | G8: 2 | H8: 309 | I8: 309 | J8: 309 | K8: =H8+5>D8 | L8: =J8<I8 | M8: TRUE | N8: TRUE | O8: allow | P8: =O8<>"unknown"
A9: 1280-off | B9: 1280 | C9: off | D9: 1240 | E9: openssl X25519 only (classical) | F9: FALSE | G9: 3 | H9: 309 | I9: 309 | J9: 309 | K9: =H9+5>D9 | L9: =J9<I9 | M9: TRUE | N9: TRUE | O9: allow | P9: =O9<>"unknown"
A10: 1280-off | B10: 1280 | C10: off | D10: 1240 | E10: openssl X25519 only (classical) | F10: FALSE | G10: 4 | H10: 309 | I10: 309 | J10: 309 | K10: =H10+5>D10 | L10: =J10<I10 | M10: TRUE | N10: TRUE | O10: allow | P10: =O10<>"unknown"
A11: 1280-off | B11: 1280 | C11: off | D11: 1240 | E11: openssl X25519 only (classical) | F11: FALSE | G11: 5 | H11: 309 | I11: 309 | J11: 309 | K11: =H11+5>D11 | L11: =J11<I11 | M11: TRUE | N11: TRUE | O11: allow | P11: =O11<>"unknown"
A12: 1280-off | B12: 1280 | C12: off | D12: 1240 | E12: openssl secp256r1 only (classical) | F12: FALSE | G12: 1 | H12: 342 | I12: 342 | J12: 342 | K12: =H12+5>D12 | L12: =J12<I12 | M12: TRUE | N12: TRUE | O12: allow | P12: =O12<>"unknown"
A13: 1280-off | B13: 1280 | C13: off | D13: 1240 | E13: openssl secp256r1 only (classical) | F13: FALSE | G13: 2 | H13: 342 | I13: 342 | J13: 342 | K13: =H13+5>D13 | L13: =J13<I13 | M13: TRUE | N13: TRUE | O13: allow | P13: =O13<>"unknown"
... A1441: 1500-on | B1441: 1500 | C1441: on | D1441: 1448 | E1441: browser tor145 | F1441: FALSE | G1441: 20 | H1441: 645 | I1441: 645 | J1441: 645 | K1441: =H1441+5>D1441 | L1441: =J1441<I1441 | M1441: TRUE | N1441: TRUE | O1441: allow | P1441: =O1441<>"unknown"

Sheet Exp4_coverage
A1: Client | B1: 1280-off | C1: 1280-on | D1: 1400-on | E1: 1460-on | F1: 1500-off | G1: 1500-on
A2: browser chrome116 | B2: =IF(COUNTIFS(Exp4!$E$2:$E$1441,"browser chrome116",Exp4!$A$2:$A$1441,"1280-off")=0,"",COUNTIFS(Exp4!$E$2:$E$1441,"browser chrome116",Exp4!$A$2:$A$1441,"1280-off",Exp4!$P$2:$P$1441,TRUE)/COUNTIFS(Exp4!$E$2:$E$1441,"browser chrome116",Exp4!$A$2:$A$1441,"1280-off")) | C2: =IF(COUNTIFS(Exp4!$E$2:$E$1441,"browser chrome116",Exp4!$A$2:$A$1441,"1280-on")=0,"",COUNTIFS(Exp4!$E$2:$E$1441,"browser chrome116",Exp4!$A$2:$A$1441,"1280-on",Exp4!$P$2:$P$1441,TRUE)/COUNTIFS(Exp4!$E$2:$E$1441,"browser chrome116",Exp4!$A$2:$A$1441,"1280-on")) | D2: =IF(COUNTIFS(Exp4!$E$2:$E$1441,"browser chrome116",Exp4!$A$2:$A$1441,"1400-on")=0,"",COUNTIFS(Exp4!$E$2:$E$1441,"browser chrome116",Exp4!$A$2:$A$1441,"1400-on",Exp4!$P$2:$P$1441,TRUE)/COUNTIFS(Exp4!$E$2:$E$1441,"browser chrome116",Exp4!$A$2:$A$1441,"1400-on")) | E2: =IF(COUNTIFS(Exp4!$E$2:$E$1441,"browser chrome116",Exp4!$A$2:$A$1441,"1460-on")=0,"",COUNTIFS(Exp4!$E$2:$E$1441,"browser chrome116",Exp4!$A$2:$A$1441,"1460-on",Exp4!$P$2:$P$1441,TRUE)/COUNTIFS(Exp4!$E$2:$E$1441,"browser chrome116",Exp4!$A$2:$A$1441,"1460-on")) | F2: =IF(COUNTIFS(Exp4!$E$2:$E$1441,"browser chrome116",Exp4!$A$2:$A$1441,"1500-off")=0,"",COUNTIFS(Exp4!$E$2:$E$1441,"browser chrome116",Exp4!$A$2:$A$1441,"1500-off",Exp4!$P$2:$P$1441,TRUE)/COUNTIFS(Exp4!$E$2:$E$1441,"browser chrome116",Exp4!$A$2:$A$1441,"1500-off")) | G2: =IF(COUNTIFS(Exp4!$E$2:$E$1441,"browser chrome116",Exp4!$A$2:$A$1441,"1500-on")=0,"",COUNTIFS(Exp4!$E$2:$E$1441,"browser chrome116",Exp4!$A$2:$A$1441,"1500-on",Exp4!$P$2:$P$1441,TRUE)/COUNTIFS(Exp4!$E$2:$E$1441,"browser chrome116",Exp4!$A$2:$A$1441,"1500-on"))
A3: browser chrome124 | B3: =IF(COUNTIFS(Exp4!$E$2:$E$1441,"browser chrome124",Exp4!$A$2:$A$1441,"1280-off")=0,"",COUNTIFS(Exp4!$E$2:$E$1441,"browser chrome124",Exp4!$A$2:$A$1441,"1280-off",Exp4!$P$2:$P$1441,TRUE)/COUNTIFS(Exp4!$E$2:$E$1441,"browser chrome124",Exp4!$A$2:$A$1441,"1280-off")) | C3: =IF(COUNTIFS(Exp4!$E$2:$E$1441,"browser chrome124",Exp4!$A$2:$A$1441,"1280-on")=0,"",COUNTIFS(Exp4!$E$2:$E$1441,"browser chrome124",Exp4!$A$2:$A$1441,"1280-on",Exp4!$P$2:$P$1441,TRUE)/COUNTIFS(Exp4!$E$2:$E$1441,"browser chrome124",Exp4!$A$2:$A$1441,"1280-on")) | D3: =IF(COUNTIFS(Exp4!$E$2:$E$1441,"browser chrome124",Exp4!$A$2:$A$1441,"1400-on")=0,"",COUNTIFS(Exp4!$E$2:$E$1441,"browser chrome124",Exp4!$A$2:$A$1441,"1400-on",Exp4!$P$2:$P$1441,TRUE)/COUNTIFS(Exp4!$E$2:$E$1441,"browser chrome124",Exp4!$A$2:$A$1441,"1400-on")) | E3: =IF(COUNTIFS(Exp4!$E$2:$E$1441,"browser chrome124",Exp4!$A$2:$A$1441,"1460-on")=0,"",COUNTIFS(Exp4!$E$2:$E$1441,"browser chrome124",Exp4!$A$2:$A$1441,"1460-on",Exp4!$P$2:$P$1441,TRUE)/COUNTIFS(Exp4!$E$2:$E$1441,"browser chrome124",Exp4!$A$2:$A$1441,"1460-on")) | F3: =IF(COUNTIFS(Exp4!$E$2:$E$1441,"browser chrome124",Exp4!$A$2:$A$1441,"1500-off")=0,"",COUNTIFS(Exp4!$E$2:$E$1441,"browser chrome124",Exp4!$A$2:$A$1441,"1500-off",Exp4!$P$2:$P$1441,TRUE)/COUNTIFS(Exp4!$E$2:$E$1441,"browser chrome124",Exp4!$A$2:$A$1441,"1500-off")) | G3: =IF(COUNTIFS(Exp4!$E$2:$E$1441,"browser chrome124",Exp4!$A$2:$A$1441,"1500-on")=0,"",COUNTIFS(Exp4!$E$2:$E$1441,"browser chrome124",Exp4!$A$2:$A$1441,"1500-on",Exp4!$P$2:$P$1441,TRUE)/COUNTIFS(Exp4!$E$2:$E$1441,"browser chrome124",Exp4!$A$2:$A$1441,"1500-on"))
A4: browser chrome131 | B4: =IF(COUNTIFS(Exp4!$E$2:$E$1441,"browser chrome131",Exp4!$A$2:$A$1441,"1280-off")=0,"",COUNTIFS(Exp4!$E$2:$E$1441,"browser chrome131",Exp4!$A$2:$A$1441,"1280-off",Exp4!$P$2:$P$1441,TRUE)/COUNTIFS(Exp4!$E$2:$E$1441,"browser chrome131",Exp4!$A$2:$A$1441,"1280-off")) | C4: =IF(COUNTIFS(Exp4!$E$2:$E$1441,"browser chrome131",Exp4!$A$2:$A$1441,"1280-on")=0,"",COUNTIFS(Exp4!$E$2:$E$1441,"browser chrome131",Exp4!$A$2:$A$1441,"1280-on",Exp4!$P$2:$P$1441,TRUE)/COUNTIFS(Exp4!$E$2:$E$1441,"browser chrome131",Exp4!$A$2:$A$1441,"1280-on")) | D4: =IF(COUNTIFS(Exp4!$E$2:$E$1441,"browser chrome131",Exp4!$A$2:$A$1441,"1400-on")=0,"",COUNTIFS(Exp4!$E$2:$E$1441,"browser chrome131",Exp4!$A$2:$A$1441,"1400-on",Exp4!$P$2:$P$1441,TRUE)/COUNTIFS(Exp4!$E$2:$E$1441,"browser chrome131",Exp4!$A$2:$A$1441,"1400-on")) | E4: =IF(COUNTIFS(Exp4!$E$2:$E$1441,"browser chrome131",Exp4!$A$2:$A$1441,"1460-on")=0,"",COUNTIFS(Exp4!$E$2:$E$1441,"browser chrome131",Exp4!$A$2:$A$1441,"1460-on",Exp4!$P$2:$P$1441,TRUE)/COUNTIFS(Exp4!$E$2:$E$1441,"browser chrome131",Exp4!$A$2:$A$1441,"1460-on")) | F4: =IF(COUNTIFS(Exp4!$E$2:$E$1441,"browser chrome131",Exp4!$A$2:$A$1441,"1500-off")=0,"",COUNTIFS(Exp4!$E$2:$E$1441,"browser chrome131",Exp4!$A$2:$A$1441,"1500-off",Exp4!$P$2:$P$1441,TRUE)/COUNTIFS(Exp4!$E$2:$E$1441,"browser chrome131",Exp4!$A$2:$A$1441,"1500-off")) | G4: =IF(COUNTIFS(Exp4!$E$2:$E$1441,"browser chrome131",Exp4!$A$2:$A$1441,"1500-on")=0,"",COUNTIFS(Exp4!$E$2:$E$1441,"browser chrome131",Exp4!$A$2:$A$1441,"1500-on",Exp4!$P$2:$P$1441,TRUE)/COUNTIFS(Exp4!$E$2:$E$1441,"browser chrome131",Exp4!$A$2:$A$1441,"1500-on"))
A5: browser chrome150 | B5: =IF(COUNTIFS(Exp4!$E$2:$E$1441,"browser chrome150",Exp4!$A$2:$A$1441,"1280-off")=0,"",COUNTIFS(Exp4!$E$2:$E$1441,"browser chrome150",Exp4!$A$2:$A$1441,"1280-off",Exp4!$P$2:$P$1441,TRUE)/COUNTIFS(Exp4!$E$2:$E$1441,"browser chrome150",Exp4!$A$2:$A$1441,"1280-off")) | C5: =IF(COUNTIFS(Exp4!$E$2:$E$1441,"browser chrome150",Exp4!$A$2:$A$1441,"1280-on")=0,"",COUNTIFS(Exp4!$E$2:$E$1441,"browser chrome150",Exp4!$A$2:$A$1441,"1280-on",Exp4!$P$2:$P$1441,TRUE)/COUNTIFS(Exp4!$E$2:$E$1441,"browser chrome150",Exp4!$A$2:$A$1441,"1280-on")) | D5: =IF(COUNTIFS(Exp4!$E$2:$E$1441,"browser chrome150",Exp4!$A$2:$A$1441,"1400-on")=0,"",COUNTIFS(Exp4!$E$2:$E$1441,"browser chrome150",Exp4!$A$2:$A$1441,"1400-on",Exp4!$P$2:$P$1441,TRUE)/COUNTIFS(Exp4!$E$2:$E$1441,"browser chrome150",Exp4!$A$2:$A$1441,"1400-on")) | E5: =IF(COUNTIFS(Exp4!$E$2:$E$1441,"browser chrome150",Exp4!$A$2:$A$1441,"1460-on")=0,"",COUNTIFS(Exp4!$E$2:$E$1441,"browser chrome150",Exp4!$A$2:$A$1441,"1460-on",Exp4!$P$2:$P$1441,TRUE)/COUNTIFS(Exp4!$E$2:$E$1441,"browser chrome150",Exp4!$A$2:$A$1441,"1460-on")) | F5: =IF(COUNTIFS(Exp4!$E$2:$E$1441,"browser chrome150",Exp4!$A$2:$A$1441,"1500-off")=0,"",COUNTIFS(Exp4!$E$2:$E$1441,"browser chrome150",Exp4!$A$2:$A$1441,"1500-off",Exp4!$P$2:$P$1441,TRUE)/COUNTIFS(Exp4!$E$2:$E$1441,"browser chrome150",Exp4!$A$2:$A$1441,"1500-off")) | G5: =IF(COUNTIFS(Exp4!$E$2:$E$1441,"browser chrome150",Exp4!$A$2:$A$1441,"1500-on")=0,"",COUNTIFS(Exp4!$E$2:$E$1441,"browser chrome150",Exp4!$A$2:$A$1441,"1500-on",Exp4!$P$2:$P$1441,TRUE)/COUNTIFS(Exp4!$E$2:$E$1441,"browser chrome150",Exp4!$A$2:$A$1441,"1500-on"))
A6: browser edge101 | B6: =IF(COUNTIFS(Exp4!$E$2:$E$1441,"browser edge101",Exp4!$A$2:$A$1441,"1280-off")=0,"",COUNTIFS(Exp4!$E$2:$E$1441,"browser edge101",Exp4!$A$2:$A$1441,"1280-off",Exp4!$P$2:$P$1441,TRUE)/COUNTIFS(Exp4!$E$2:$E$1441,"browser edge101",Exp4!$A$2:$A$1441,"1280-off")) | C6: =IF(COUNTIFS(Exp4!$E$2:$E$1441,"browser edge101",Exp4!$A$2:$A$1441,"1280-on")=0,"",COUNTIFS(Exp4!$E$2:$E$1441,"browser edge101",Exp4!$A$2:$A$1441,"1280-on",Exp4!$P$2:$P$1441,TRUE)/COUNTIFS(Exp4!$E$2:$E$1441,"browser edge101",Exp4!$A$2:$A$1441,"1280-on")) | D6: =IF(COUNTIFS(Exp4!$E$2:$E$1441,"browser edge101",Exp4!$A$2:$A$1441,"1400-on")=0,"",COUNTIFS(Exp4!$E$2:$E$1441,"browser edge101",Exp4!$A$2:$A$1441,"1400-on",Exp4!$P$2:$P$1441,TRUE)/COUNTIFS(Exp4!$E$2:$E$1441,"browser edge101",Exp4!$A$2:$A$1441,"1400-on")) | E6: =IF(COUNTIFS(Exp4!$E$2:$E$1441,"browser edge101",Exp4!$A$2:$A$1441,"1460-on")=0,"",COUNTIFS(Exp4!$E$2:$E$1441,"browser edge101",Exp4!$A$2:$A$1441,"1460-on",Exp4!$P$2:$P$1441,TRUE)/COUNTIFS(Exp4!$E$2:$E$1441,"browser edge101",Exp4!$A$2:$A$1441,"1460-on")) | F6: =IF(COUNTIFS(Exp4!$E$2:$E$1441,"browser edge101",Exp4!$A$2:$A$1441,"1500-off")=0,"",COUNTIFS(Exp4!$E$2:$E$1441,"browser edge101",Exp4!$A$2:$A$1441,"1500-off",Exp4!$P$2:$P$1441,TRUE)/COUNTIFS(Exp4!$E$2:$E$1441,"browser edge101",Exp4!$A$2:$A$1441,"1500-off")) | G6: =IF(COUNTIFS(Exp4!$E$2:$E$1441,"browser edge101",Exp4!$A$2:$A$1441,"1500-on")=0,"",COUNTIFS(Exp4!$E$2:$E$1441,"browser edge101",Exp4!$A$2:$A$1441,"1500-on",Exp4!$P$2:$P$1441,TRUE)/COUNTIFS(Exp4!$E$2:$E$1441,"browser edge101",Exp4!$A$2:$A$1441,"1500-on"))
A7: browser firefox133 | B7: =IF(COUNTIFS(Exp4!$E$2:$E$1441,"browser firefox133",Exp4!$A$2:$A$1441,"1280-off")=0,"",COUNTIFS(Exp4!$E$2:$E$1441,"browser firefox133",Exp4!$A$2:$A$1441,"1280-off",Exp4!$P$2:$P$1441,TRUE)/COUNTIFS(Exp4!$E$2:$E$1441,"browser firefox133",Exp4!$A$2:$A$1441,"1280-off")) | C7: =IF(COUNTIFS(Exp4!$E$2:$E$1441,"browser firefox133",Exp4!$A$2:$A$1441,"1280-on")=0,"",COUNTIFS(Exp4!$E$2:$E$1441,"browser firefox133",Exp4!$A$2:$A$1441,"1280-on",Exp4!$P$2:$P$1441,TRUE)/COUNTIFS(Exp4!$E$2:$E$1441,"browser firefox133",Exp4!$A$2:$A$1441,"1280-on")) | D7: =IF(COUNTIFS(Exp4!$E$2:$E$1441,"browser firefox133",Exp4!$A$2:$A$1441,"1400-on")=0,"",COUNTIFS(Exp4!$E$2:$E$1441,"browser firefox133",Exp4!$A$2:$A$1441,"1400-on",Exp4!$P$2:$P$1441,TRUE)/COUNTIFS(Exp4!$E$2:$E$1441,"browser firefox133",Exp4!$A$2:$A$1441,"1400-on")) | E7: =IF(COUNTIFS(Exp4!$E$2:$E$1441,"browser firefox133",Exp4!$A$2:$A$1441,"1460-on")=0,"",COUNTIFS(Exp4!$E$2:$E$1441,"browser firefox133",Exp4!$A$2:$A$1441,"1460-on",Exp4!$P$2:$P$1441,TRUE)/COUNTIFS(Exp4!$E$2:$E$1441,"browser firefox133",Exp4!$A$2:$A$1441,"1460-on")) | F7: =IF(COUNTIFS(Exp4!$E$2:$E$1441,"browser firefox133",Exp4!$A$2:$A$1441,"1500-off")=0,"",COUNTIFS(Exp4!$E$2:$E$1441,"browser firefox133",Exp4!$A$2:$A$1441,"1500-off",Exp4!$P$2:$P$1441,TRUE)/COUNTIFS(Exp4!$E$2:$E$1441,"browser firefox133",Exp4!$A$2:$A$1441,"1500-off")) | G7: =IF(COUNTIFS(Exp4!$E$2:$E$1441,"browser firefox133",Exp4!$A$2:$A$1441,"1500-on")=0,"",COUNTIFS(Exp4!$E$2:$E$1441,"browser firefox133",Exp4!$A$2:$A$1441,"1500-on",Exp4!$P$2:$P$1441,TRUE)/COUNTIFS(Exp4!$E$2:$E$1441,"browser firefox133",Exp4!$A$2:$A$1441,"1500-on"))
A8: browser firefox147 | B8: =IF(COUNTIFS(Exp4!$E$2:$E$1441,"browser firefox147",Exp4!$A$2:$A$1441,"1280-off")=0,"",COUNTIFS(Exp4!$E$2:$E$1441,"browser firefox147",Exp4!$A$2:$A$1441,"1280-off",Exp4!$P$2:$P$1441,TRUE)/COUNTIFS(Exp4!$E$2:$E$1441,"browser firefox147",Exp4!$A$2:$A$1441,"1280-off")) | C8: =IF(COUNTIFS(Exp4!$E$2:$E$1441,"browser firefox147",Exp4!$A$2:$A$1441,"1280-on")=0,"",COUNTIFS(Exp4!$E$2:$E$1441,"browser firefox147",Exp4!$A$2:$A$1441,"1280-on",Exp4!$P$2:$P$1441,TRUE)/COUNTIFS(Exp4!$E$2:$E$1441,"browser firefox147",Exp4!$A$2:$A$1441,"1280-on")) | D8: =IF(COUNTIFS(Exp4!$E$2:$E$1441,"browser firefox147",Exp4!$A$2:$A$1441,"1400-on")=0,"",COUNTIFS(Exp4!$E$2:$E$1441,"browser firefox147",Exp4!$A$2:$A$1441,"1400-on",Exp4!$P$2:$P$1441,TRUE)/COUNTIFS(Exp4!$E$2:$E$1441,"browser firefox147",Exp4!$A$2:$A$1441,"1400-on")) | E8: =IF(COUNTIFS(Exp4!$E$2:$E$1441,"browser firefox147",Exp4!$A$2:$A$1441,"1460-on")=0,"",COUNTIFS(Exp4!$E$2:$E$1441,"browser firefox147",Exp4!$A$2:$A$1441,"1460-on",Exp4!$P$2:$P$1441,TRUE)/COUNTIFS(Exp4!$E$2:$E$1441,"browser firefox147",Exp4!$A$2:$A$1441,"1460-on")) | F8: =IF(COUNTIFS(Exp4!$E$2:$E$1441,"browser firefox147",Exp4!$A$2:$A$1441,"1500-off")=0,"",COUNTIFS(Exp4!$E$2:$E$1441,"browser firefox147",Exp4!$A$2:$A$1441,"1500-off",Exp4!$P$2:$P$1441,TRUE)/COUNTIFS(Exp4!$E$2:$E$1441,"browser firefox147",Exp4!$A$2:$A$1441,"1500-off")) | G8: =IF(COUNTIFS(Exp4!$E$2:$E$1441,"browser firefox147",Exp4!$A$2:$A$1441,"1500-on")=0,"",COUNTIFS(Exp4!$E$2:$E$1441,"browser firefox147",Exp4!$A$2:$A$1441,"1500-on",Exp4!$P$2:$P$1441,TRUE)/COUNTIFS(Exp4!$E$2:$E$1441,"browser firefox147",Exp4!$A$2:$A$1441,"1500-on"))
A9: browser safari184 | B9: =IF(COUNTIFS(Exp4!$E$2:$E$1441,"browser safari184",Exp4!$A$2:$A$1441,"1280-off")=0,"",COUNTIFS(Exp4!$E$2:$E$1441,"browser safari184",Exp4!$A$2:$A$1441,"1280-off",Exp4!$P$2:$P$1441,TRUE)/COUNTIFS(Exp4!$E$2:$E$1441,"browser safari184",Exp4!$A$2:$A$1441,"1280-off")) | C9: =IF(COUNTIFS(Exp4!$E$2:$E$1441,"browser safari184",Exp4!$A$2:$A$1441,"1280-on")=0,"",COUNTIFS(Exp4!$E$2:$E$1441,"browser safari184",Exp4!$A$2:$A$1441,"1280-on",Exp4!$P$2:$P$1441,TRUE)/COUNTIFS(Exp4!$E$2:$E$1441,"browser safari184",Exp4!$A$2:$A$1441,"1280-on")) | D9: =IF(COUNTIFS(Exp4!$E$2:$E$1441,"browser safari184",Exp4!$A$2:$A$1441,"1400-on")=0,"",COUNTIFS(Exp4!$E$2:$E$1441,"browser safari184",Exp4!$A$2:$A$1441,"1400-on",Exp4!$P$2:$P$1441,TRUE)/COUNTIFS(Exp4!$E$2:$E$1441,"browser safari184",Exp4!$A$2:$A$1441,"1400-on")) | E9: =IF(COUNTIFS(Exp4!$E$2:$E$1441,"browser safari184",Exp4!$A$2:$A$1441,"1460-on")=0,"",COUNTIFS(Exp4!$E$2:$E$1441,"browser safari184",Exp4!$A$2:$A$1441,"1460-on",Exp4!$P$2:$P$1441,TRUE)/COUNTIFS(Exp4!$E$2:$E$1441,"browser safari184",Exp4!$A$2:$A$1441,"1460-on")) | F9: =IF(COUNTIFS(Exp4!$E$2:$E$1441,"browser safari184",Exp4!$A$2:$A$1441,"1500-off")=0,"",COUNTIFS(Exp4!$E$2:$E$1441,"browser safari184",Exp4!$A$2:$A$1441,"1500-off",Exp4!$P$2:$P$1441,TRUE)/COUNTIFS(Exp4!$E$2:$E$1441,"browser safari184",Exp4!$A$2:$A$1441,"1500-off")) | G9: =IF(COUNTIFS(Exp4!$E$2:$E$1441,"browser safari184",Exp4!$A$2:$A$1441,"1500-on")=0,"",COUNTIFS(Exp4!$E$2:$E$1441,"browser safari184",Exp4!$A$2:$A$1441,"1500-on",Exp4!$P$2:$P$1441,TRUE)/COUNTIFS(Exp4!$E$2:$E$1441,"browser safari184",Exp4!$A$2:$A$1441,"1500-on"))
A10: browser safari260 | B10: =IF(COUNTIFS(Exp4!$E$2:$E$1441,"browser safari260",Exp4!$A$2:$A$1441,"1280-off")=0,"",COUNTIFS(Exp4!$E$2:$E$1441,"browser safari260",Exp4!$A$2:$A$1441,"1280-off",Exp4!$P$2:$P$1441,TRUE)/COUNTIFS(Exp4!$E$2:$E$1441,"browser safari260",Exp4!$A$2:$A$1441,"1280-off")) | C10: =IF(COUNTIFS(Exp4!$E$2:$E$1441,"browser safari260",Exp4!$A$2:$A$1441,"1280-on")=0,"",COUNTIFS(Exp4!$E$2:$E$1441,"browser safari260",Exp4!$A$2:$A$1441,"1280-on",Exp4!$P$2:$P$1441,TRUE)/COUNTIFS(Exp4!$E$2:$E$1441,"browser safari260",Exp4!$A$2:$A$1441,"1280-on")) | D10: =IF(COUNTIFS(Exp4!$E$2:$E$1441,"browser safari260",Exp4!$A$2:$A$1441,"1400-on")=0,"",COUNTIFS(Exp4!$E$2:$E$1441,"browser safari260",Exp4!$A$2:$A$1441,"1400-on",Exp4!$P$2:$P$1441,TRUE)/COUNTIFS(Exp4!$E$2:$E$1441,"browser safari260",Exp4!$A$2:$A$1441,"1400-on")) | E10: =IF(COUNTIFS(Exp4!$E$2:$E$1441,"browser safari260",Exp4!$A$2:$A$1441,"1460-on")=0,"",COUNTIFS(Exp4!$E$2:$E$1441,"browser safari260",Exp4!$A$2:$A$1441,"1460-on",Exp4!$P$2:$P$1441,TRUE)/COUNTIFS(Exp4!$E$2:$E$1441,"browser safari260",Exp4!$A$2:$A$1441,"1460-on")) | F10: =IF(COUNTIFS(Exp4!$E$2:$E$1441,"browser safari260",Exp4!$A$2:$A$1441,"1500-off")=0,"",COUNTIFS(Exp4!$E$2:$E$1441,"browser safari260",Exp4!$A$2:$A$1441,"1500-off",Exp4!$P$2:$P$1441,TRUE)/COUNTIFS(Exp4!$E$2:$E$1441,"browser safari260",Exp4!$A$2:$A$1441,"1500-off")) | G10: =IF(COUNTIFS(Exp4!$E$2:$E$1441,"browser safari260",Exp4!$A$2:$A$1441,"1500-on")=0,"",COUNTIFS(Exp4!$E$2:$E$1441,"browser safari260",Exp4!$A$2:$A$1441,"1500-on",Exp4!$P$2:$P$1441,TRUE)/COUNTIFS(Exp4!$E$2:$E$1441,"browser safari260",Exp4!$A$2:$A$1441,"1500-on"))
A11: browser safari260_ios | B11: =IF(COUNTIFS(Exp4!$E$2:$E$1441,"browser safari260_ios",Exp4!$A$2:$A$1441,"1280-off")=0,"",COUNTIFS(Exp4!$E$2:$E$1441,"browser safari260_ios",Exp4!$A$2:$A$1441,"1280-off",Exp4!$P$2:$P$1441,TRUE)/COUNTIFS(Exp4!$E$2:$E$1441,"browser safari260_ios",Exp4!$A$2:$A$1441,"1280-off")) | C11: =IF(COUNTIFS(Exp4!$E$2:$E$1441,"browser safari260_ios",Exp4!$A$2:$A$1441,"1280-on")=0,"",COUNTIFS(Exp4!$E$2:$E$1441,"browser safari260_ios",Exp4!$A$2:$A$1441,"1280-on",Exp4!$P$2:$P$1441,TRUE)/COUNTIFS(Exp4!$E$2:$E$1441,"browser safari260_ios",Exp4!$A$2:$A$1441,"1280-on")) | D11: =IF(COUNTIFS(Exp4!$E$2:$E$1441,"browser safari260_ios",Exp4!$A$2:$A$1441,"1400-on")=0,"",COUNTIFS(Exp4!$E$2:$E$1441,"browser safari260_ios",Exp4!$A$2:$A$1441,"1400-on",Exp4!$P$2:$P$1441,TRUE)/COUNTIFS(Exp4!$E$2:$E$1441,"browser safari260_ios",Exp4!$A$2:$A$1441,"1400-on")) | E11: =IF(COUNTIFS(Exp4!$E$2:$E$1441,"browser safari260_ios",Exp4!$A$2:$A$1441,"1460-on")=0,"",COUNTIFS(Exp4!$E$2:$E$1441,"browser safari260_ios",Exp4!$A$2:$A$1441,"1460-on",Exp4!$P$2:$P$1441,TRUE)/COUNTIFS(Exp4!$E$2:$E$1441,"browser safari260_ios",Exp4!$A$2:$A$1441,"1460-on")) | F11: =IF(COUNTIFS(Exp4!$E$2:$E$1441,"browser safari260_ios",Exp4!$A$2:$A$1441,"1500-off")=0,"",COUNTIFS(Exp4!$E$2:$E$1441,"browser safari260_ios",Exp4!$A$2:$A$1441,"1500-off",Exp4!$P$2:$P$1441,TRUE)/COUNTIFS(Exp4!$E$2:$E$1441,"browser safari260_ios",Exp4!$A$2:$A$1441,"1500-off")) | G11: =IF(COUNTIFS(Exp4!$E$2:$E$1441,"browser safari260_ios",Exp4!$A$2:$A$1441,"1500-on")=0,"",COUNTIFS(Exp4!$E$2:$E$1441,"browser safari260_ios",Exp4!$A$2:$A$1441,"1500-on",Exp4!$P$2:$P$1441,TRUE)/COUNTIFS(Exp4!$E$2:$E$1441,"browser safari260_ios",Exp4!$A$2:$A$1441,"1500-on"))
